1. Issues pulling data
2. Split up by part. Currently just tring to get population df to print 

example error :
"PS C:\Users\lenovo\Desktop\SSRC> python -u "c:\Users\lenovo\Desktop\SSRC\test.py"
C:\Users\lenovo\AppData\Local\Programs\Python\Python311\Lib\site-packages\fuzzywuzzy\fuzz.py:11: UserWarning: Using slow pure-python SequenceMatcher. Install python-Levenshtein to remove this warning
  warnings.warn('Using slow pure-python SequenceMatcher. Install python-Levenshtein to remove this warning')
Traceback (most recent call last):
  File "c:\Users\lenovo\Desktop\SSRC\test.py", line 5, in <module>
    cenpy.settings.apikey = "5b498d1ae7076f392073d199334c5cc03aba91bc"
    ^^^^^^^^^^^^^^
AttributeError: module 'cenpy' has no attribute 'settings'"
__________________________________________________________________
"Running ... 
Traceback (most recent call last):
  File "c:\Users\lenovo\Desktop\SSRC\test.py", line 7, in <module>
    c = cenpy.remote.APIConnection(apikey="5b498d1ae7076f392073d199334c5cc03aba91bc")
        ^^^^^^^^^^^^^^^^^^^^^^^^^^^^^^^^^^^^^^^^^^^^^^^^^^^^^^^^^^^^^^^^^^^^^^^^^^^^^
  File "C:\Users\lenovo\AppData\Local\Programs\Python\Python311\Lib\site-packages\cenpy\remote.py", line 34, in __init__
    if "eits" not in api_name and api_name is not None:
       ^^^^^^^^^^^^^^^^^^^^^^
TypeError: argument of type 'NoneType' is not iterable"  
_____________________________________________________________________
Running ... 
Traceback (most recent call last):
  File "c:\Users\lenovo\Desktop\SSRC\test.py", line 17, in <module>
    population_df = cenpy.query("ACSDT5Y", geo_unit=nyc_city, year=2021)
                    ^^^^^^^^^^^
AttributeError: module 'cenpy' has no attribute 'query'
_____________________________________________________________________
SUCCESSFUL PULL?

Running ... 
Traceback (most recent call last):
  File "C:\Users\lenovo\AppData\Local\Programs\Python\Python311\Lib\site-packages\requests\models.py", line 971, in json
    return complexjson.loads(self.text, **kwargs)
           ^^^^^^^^^^^^^^^^^^^^^^^^^^^^^^^^^^^^^^
  File "C:\Users\lenovo\AppData\Local\Programs\Python\Python311\Lib\json\__init__.py", line 346, in loads
    return _default_decoder.decode(s)
           ^^^^^^^^^^^^^^^^^^^^^^^^^^
  File "C:\Users\lenovo\AppData\Local\Programs\Python\Python311\Lib\json\decoder.py", line 337, in decode
    obj, end = self.raw_decode(s, idx=_w(s, 0).end())
               ^^^^^^^^^^^^^^^^^^^^^^^^^^^^^^^^^^^^^^
  File "C:\Users\lenovo\AppData\Local\Programs\Python\Python311\Lib\json\decoder.py", line 355, in raw_decode
    raise JSONDecodeError("Expecting value", s, err.value) from None
json.decoder.JSONDecodeError: Expecting value: line 1 column 1 (char 0)

During handling of the above exception, another exception occurred:

Traceback (most recent call last):
  File "C:\Users\lenovo\AppData\Local\Programs\Python\Python311\Lib\site-packages\censusdata\download.py", line 36, in _download
    data = r.json()
           ^^^^^^^^
  File "C:\Users\lenovo\AppData\Local\Programs\Python\Python311\Lib\site-packages\requests\models.py", line 975, in json
    raise RequestsJSONDecodeError(e.msg, e.doc, e.pos)
requests.exceptions.JSONDecodeError: Expecting value: line 1 column 1 (char 0)

During handling of the above exception, another exception occurred:

Traceback (most recent call last):
  File "c:\Users\lenovo\Desktop\SSRC\test.py", line 19, in <module>
    population_df = censusdata.download(src="acs5", year=2021, geo=censusdata.censusgeo([(nyc_city, "New York city")]), var=['B01003_001E'])
                    ^^^^^^^^^^^^^^^^^^^^^^^^^^^^^^^^^^^^^^^^^^^^^^^^^^^^^^^^^^^^^^^^^^^^^^^^^^^^^^^^^^^^^^^^^^^^^^^^^^^^^^^^^^^^^^^^^^^^^^^^
  File "C:\Users\lenovo\AppData\Local\Programs\Python\Python311\Lib\site-packages\censusdata\download.py", line 116, in download
    data.update(_download(src + tabletype, year, params, endpt=endpt))
                ^^^^^^^^^^^^^^^^^^^^^^^^^^^^^^^^^^^^^^^^^^^^^^^^^^^^^
  File "C:\Users\lenovo\AppData\Local\Programs\Python\Python311\Lib\site-packages\censusdata\download.py", line 38, in _download
    raise ValueError('Unexpected response (URL: {0.url}): {0.text} '.format(r))
ValueError: Unexpected response (URL: https://api.census.gov/data/2021/acs/acs5?get=NAME,B01003_001E&for=140%7C16000US3651000:New%20York%20city): error: invalid 'for' argument
_____________________________________________________________________________________________________________________________________________________________________________________

1. I've attempted to try and use censusdata, and cenpy to pull

2. back and forth with chatgpt

3. Found this video on how to pull data from census but I'm not sure how accurate it is on our use case since we have very specific labels. If you have the time pls verify
https://www.youtube.com/watch?v=LW-M_UC0VTE


4